<?xml version="1.0" ?>
<!-- =================================================================================== -->
<!-- |    This document was autogenerated by xacro from /home/chris/local-git/MCRL-HRI-001/_software/touchscreen_robot_ws/src/touchscreen_robot_description_pkg/urdf/touchscreen_robot_la.urdf.xacro | -->
<!-- |    EDITING THIS FILE BY HAND IS NOT RECOMMENDED                                 | -->
<!-- =================================================================================== -->
<!-- Touchscreen Robot -->
<robot name="touchscreen_robot">
    <!-- World -->
    <gazebo reference="world">
        <plugin name="gazebo_ros_control">
            <robotNamespace>/</robotNamespace>
        </plugin>
    </gazebo>
    <!-- Base Link -->
    <gazebo reference="base_link">
        <kp>1000000.0</kp>
        <kd>100.0</kd>
        <mu1>30.0</mu1>
        <mu2>30.0</mu2>
        <maxVel>1.0</maxVel>
        <minDepth>0.001</minDepth>
        <material>Gazebo/DarkGrey</material>
    </gazebo>
    <!-- Link1 -->
    <gazebo reference="link_1">
        <kp>1000000.0</kp>
        <kd>100.0</kd>
        <mu1>30.0</mu1>
        <mu2>30.0</mu2>
        <maxVel>1.0</maxVel>
        <minDepth>0.001</minDepth>
        <material>Gazebo/DarkGrey</material>
    </gazebo>
    <!-- Link2 -->
    <gazebo reference="link_2">
        <kp>1000000.0</kp>
        <kd>100.0</kd>
        <mu1>30.0</mu1>
        <mu2>30.0</mu2>
        <maxVel>1.0</maxVel>
        <minDepth>0.001</minDepth>
        <material>Gazebo/DarkGrey</material>
    </gazebo>
    <!-- Link3 -->
    <gazebo reference="link_3">
        <kp>1000000.0</kp>
        <kd>100.0</kd>
        <mu1>30.0</mu1>
        <mu2>30.0</mu2>
        <maxVel>1.0</maxVel>
        <minDepth>0.001</minDepth>
        <material>Gazebo/DarkGrey</material>
    </gazebo>
    <!-- Link4 -->
    <gazebo reference="link_4">
        <kp>1000000.0</kp>
        <kd>100.0</kd>
        <mu1>30.0</mu1>
        <mu2>30.0</mu2>
        <maxVel>1.0</maxVel>
        <minDepth>0.001</minDepth>
        <material>Gazebo/DarkGrey</material>
    </gazebo>
    <!-- Link5 -->
    <gazebo reference="link_5">
        <kp>1000000.0</kp>
        <kd>100.0</kd>
        <mu1>30.0</mu1>
        <mu2>30.0</mu2>
        <maxVel>1.0</maxVel>
        <minDepth>0.001</minDepth>
        <material>Gazebo/DarkGrey</material>
    </gazebo>
    <!-- Link6 -->
    <gazebo reference="link_6">
        <kp>1000000.0</kp>
        <kd>100.0</kd>
        <mu1>30.0</mu1>
        <mu2>30.0</mu2>
        <maxVel>1.0</maxVel>
        <minDepth>0.001</minDepth>
        <material>Gazebo/DarkGrey</material>
    </gazebo>
    <!-- handeye_target_frame -->
    <gazebo reference="handeye_target_frame">
        <kp>1000000.0</kp>
        <kd>100.0</kd>
        <mu1>30.0</mu1>
        <mu2>30.0</mu2>
        <maxVel>1.0</maxVel>
        <minDepth>0.001</minDepth>
        <material>Gazebo/DarkGrey</material>
    </gazebo>
    <!-- linear_link -->
    <gazebo reference="linear_link">
        <kp>1000000.0</kp>
        <kd>100.0</kd>
        <mu1>30.0</mu1>
        <mu2>30.0</mu2>
        <maxVel>1.0</maxVel>
        <minDepth>0.001</minDepth>
        <material>Gazebo/DarkGrey</material>
    </gazebo>
    <gazebo>
        <plugin filename="libgazebo_ros_control.so" name="gazebo_ros_control">
            <robotNamespace />
            <controlPeriod>0.001</controlPeriod>
            <robotSimType>gazebo_ros_control/DefaultRobotHWSim</robotSimType>
        </plugin>
    </gazebo>
    <material name="black">
        <color rgba="0.0 0.0 0.0 1.0" />
    </material>
    <material name="white">
        <color rgba="1.0 1.0 1.0 1.0" />
    </material>
    <material name="red">
        <color rgba="0.8 0.0 0.0 1.0" />
    </material>
    <material name="blue">
        <color rgba="0.0 0.0 0.8 1.0" />
    </material>
    <material name="green">
        <color rgba="0.0 0.8 0.0 1.0" />
    </material>
    <material name="grey">
        <color rgba="0.5 0.5 0.5 1.0" />
    </material>
    <material name="orange">
        <color rgba="1.0 0.4235294117647059 0.0392156862745098 1.0" />
    </material>
    <material name="brown">
        <color rgba="0.8705882352941177 0.8117647058823529 0.7647058823529411 1.0" />
    </material>
    <material name="urdf_exported_color">
        <color rgba="0.75294 0.75294 0.75294 1" />
    </material>
    <!-- TOUCHSCREEN_ROBOT_LINEAR ACTUATOR -->
    <!-- _________________________________ -->
    <!-- World -->
    <link name="world" />
    <!-- World fixed joint -->
    <joint name="world_fixed" type="fixed">
        <parent link="world" />
        <child link="base_link" />
    </joint>
    <!-- Base Link -->
    <link name="base_link">
        <inertial>
            <mass value="0.14193" />
            <origin xyz="-0.006946 -0.00019533 0.029463" rpy="0 0 0" />
            <inertia ixx="0.00011717" ixy="2.9776e-08" ixz="-6.3575e-08" iyy="0.00012562" iyz="1.1602e-08" izz="0.00019319" />
        </inertial>
        <visual>
            <geometry>
                <mesh filename="package://touchscreen_robot_description_pkg/meshes/touchscreen_robot_la/base_link.STL" />
            </geometry>
            <material name="urdf_exported_color" />
        </visual>
        <collision>
            <geometry>
                <mesh filename="package://touchscreen_robot_description_pkg/meshes/touchscreen_robot_la/base_link.STL" />
            </geometry>
        </collision>
    </link>
    <!-- Link 1 -->
    <link name="link_1">
        <visual>
            <geometry>
                <mesh filename="package://touchscreen_robot_description_pkg/meshes/touchscreen_robot_la/link_1.STL" />
            </geometry>
            <material name="urdf_exported_color" />
        </visual>
        <collision>
            <geometry>
                <mesh filename="package://touchscreen_robot_description_pkg/meshes/touchscreen_robot_la/link_1.STL" />
            </geometry>
        </collision>
        <inertial>
            <mass value="0.10456" />
            <origin xyz="-0.0003872 -4.9375e-05 0.034568" rpy="0 0 0" />
            <inertia ixx="5.0475e-05" ixy="-2.143e-09" ixz="-1.0116e-08" iyy="4.2692e-05" iyz="-3.4032e-07" izz="4.2906e-05" />
        </inertial>
    </link>
    <!-- Joint 1 -->
    <joint name="joint_1" type="revolute">
        <parent link="base_link" />
        <child link="link_1" />
        <origin rpy="0 0 0" xyz="0 0 0.051" />
        <axis xyz="0 0 1" />
        <limit effort="3.1" lower="-3.141592653589793" upper="3.141592653589793" velocity="8" />
    </joint>
    <!-- Transmission 1 -->
    <transmission name="tran1">
        <type>transmission_interface/SimpleTransmission</type>
        <joint name="joint_1">
            <hardwareInterface>hardware_interface/PositionJointInterface</hardwareInterface>
        </joint>
        <actuator name="motor1">
            <hardwareInterface>hardware_interface/PositionJointInterface</hardwareInterface>
            <mechanicalReduction>1</mechanicalReduction>
        </actuator>
    </transmission>
    <!--  Link 2-->
    <link name="link_2">
        <visual>
            <geometry>
                <mesh filename="package://touchscreen_robot_description_pkg/meshes/touchscreen_robot_la/link_2.STL" />
            </geometry>
            <material name="urdf_exported_color" />
        </visual>
        <collision>
            <geometry>
                <mesh filename="package://touchscreen_robot_description_pkg/meshes/touchscreen_robot_la/link_2.STL" />
            </geometry>
        </collision>
        <inertial>
            <mass value="0.088808" />
            <origin xyz="0.00031891 0.0019583 0.12113" rpy="0 0 0" />
            <inertia ixx="3.7386e-05" ixy="-4.1967e-11" ixz="1.3574e-08" iyy="2.8904e-05" iyz="5.0692e-07" izz="2.2929e-05" />
        </inertial>
    </link>
    <!--  Joint 2 -->
    <joint name="joint_2" type="revolute">
        <parent link="link_1" />
        <child link="link_2" />
        <origin rpy="0 0 0" xyz="-0.0005 0 0.0563" />
        <axis xyz="0 1 0" />
        <!--changed from -1 to 1 March 22  -->
        <limit effort="20" lower="-1.92" upper="1.92" velocity="8" />
    </joint>
    <!-- Transmission 2 -->
    <transmission name="tran2">
        <type>transmission_interface/SimpleTransmission</type>
        <joint name="joint_2">
            <hardwareInterface>hardware_interface/PositionJointInterface</hardwareInterface>
        </joint>
        <actuator name="motor2">
            <hardwareInterface>hardware_interface/PositionJointInterface</hardwareInterface>
            <mechanicalReduction>1</mechanicalReduction>
        </actuator>
    </transmission>
    <!--  Link 3 -->
    <link name="link_3">
        <visual>
            <geometry>
                <mesh filename="package://touchscreen_robot_description_pkg/meshes/touchscreen_robot_la/link_3.STL" />
            </geometry>
            <material name="urdf_exported_color" />
        </visual>
        <collision>
            <geometry>
                <mesh filename="package://touchscreen_robot_description_pkg/meshes/touchscreen_robot_la/link_3.STL" />
            </geometry>
        </collision>
        <inertial>
            <mass value="0.0622144266577011" />
            <origin xyz="0.0051817 0.0024432 0.055521" rpy="0 0 0" />
            <inertia ixx="1.3036e-05" ixy="-1.1838e-09" ixz="1.8283e-07" iyy="1.648e-05" iyz="-2.2325e-10" izz="1.4977e-05" />
        </inertial>
    </link>
    <!--  Joint 3 (axis xyz="-0.00010512 1 0")-->
    <joint name="joint_3" type="revolute">
        <parent link="link_2" />
        <child link="link_3" />
        <origin rpy="0 0 0" xyz="0 0 0.1578" />
        <axis xyz="0 -1 0" />
        <!--changed from -1 to 1 March 22  -->
        <limit effort="20" lower="-1.92" upper="1.92" velocity="8" />
    </joint>
    <!-- Transmission 3 -->
    <transmission name="tran3">
        <type>transmission_interface/SimpleTransmission</type>
        <joint name="joint_3">
            <hardwareInterface>hardware_interface/PositionJointInterface</hardwareInterface>
        </joint>
        <actuator name="motor3">
            <hardwareInterface>hardware_interface/PositionJointInterface</hardwareInterface>
            <mechanicalReduction>1</mechanicalReduction>
        </actuator>
    </transmission>
    <!--  Link 4 -->
    <link name="link_4">
        <visual>
            <geometry>
                <mesh filename="package://touchscreen_robot_description_pkg/meshes/touchscreen_robot_la/link_4.STL" />
            </geometry>
            <material name="urdf_exported_color" />
        </visual>
        <collision>
            <geometry>
                <mesh filename="package://touchscreen_robot_description_pkg/meshes/touchscreen_robot_la/link_4.STL" />
            </geometry>
        </collision>
        <inertial>
            <mass value="0.052995" />
            <origin xyz="-1.9816e-06 3.4172e-05 0.033429" rpy="0 0 0" />
            <inertia ixx="1.301e-05" ixy="2.2325e-10" ixz="1.1838e-09" iyy="1.0997e-05" iyz="1.8283e-07" izz="8.7538e-06" />
        </inertial>
    </link>
    <!--  Joint 4-->
    <joint name="joint_4" type="revolute">
        <parent link="link_3" />
        <child link="link_4" />
        <origin rpy="0 0 0" xyz="0.004 -0.0025001 0.0826" />
        <axis xyz="0 0 1" />
        <!--changed from -1 to 1 March 22  -->
        <limit effort="20" lower="-3.141592653589793" upper="3.141592653589793" velocity="8" />
    </joint>
    <!-- Transmission 4 -->
    <transmission name="tran4">
        <type>transmission_interface/SimpleTransmission</type>
        <joint name="joint_4">
            <hardwareInterface>hardware_interface/PositionJointInterface</hardwareInterface>
        </joint>
        <actuator name="motor4">
            <hardwareInterface>hardware_interface/PositionJointInterface</hardwareInterface>
            <mechanicalReduction>1</mechanicalReduction>
        </actuator>
    </transmission>
    <!--  Link 5 -->
    <link name="link_5">
        <visual>
            <geometry>
                <mesh filename="package://touchscreen_robot_description_pkg/meshes/touchscreen_robot_la/link_5.STL" />
            </geometry>
            <material name="urdf_exported_color" />
        </visual>
        <collision>
            <geometry>
                <mesh filename="package://touchscreen_robot_description_pkg/meshes/touchscreen_robot_la/link_5.STL" />
            </geometry>
        </collision>
        <inertial>
            <mass value="0.051937" />
            <origin xyz="-3.2918e-05 0.00039798 0.056142" rpy="0 0 0" />
            <inertia ixx="1.2259e-05" ixy="-2.2363e-10" ixz="-1.8283e-07" iyy="1.3365e-05" iyz="1.1838e-09" izz="9.71e-06" />
        </inertial>
    </link>
    <!--  Joint 5-->
    <joint name="joint_5" type="revolute">
        <parent link="link_4" />
        <child link="link_5" />
        <origin rpy="0 0 0" xyz="0 0 0.04995" />
        <axis xyz="0 -1 0" />
        <!--changed from -1 to 1 March 22  -->
        <limit effort="20" lower="-2.0" upper="2.0" velocity="8" />
    </joint>
    <!-- Transmission 5 -->
    <transmission name="tran5">
        <type>transmission_interface/SimpleTransmission</type>
        <joint name="joint_5">
            <hardwareInterface>hardware_interface/PositionJointInterface</hardwareInterface>
        </joint>
        <actuator name="motor5">
            <hardwareInterface>hardware_interface/PositionJointInterface</hardwareInterface>
            <mechanicalReduction>1</mechanicalReduction>
        </actuator>
    </transmission>
    <!--  Link 6 -->
    <link name="link_6">
        <visual>
            <geometry>
                <mesh filename="package://touchscreen_robot_description_pkg/meshes/touchscreen_robot_la/link_6.STL" />
            </geometry>
            <material name="urdf_exported_color" />
        </visual>
        <collision>
            <geometry>
                <mesh filename="package://touchscreen_robot_description_pkg/meshes/touchscreen_robot_la/link_6.STL" />
            </geometry>
        </collision>
        <inertial>
            <mass value="0.065949" />
            <origin xyz="-0.00012385 0.0028119 0.065419" rpy="0 0 0" />
            <inertia ixx="3.1696e-05" ixy="1.1636e-08" ixz="-1.2131e-06" iyy="3.126e-05" iyz="-9.8425e-08" izz="1.1854e-05" />
        </inertial>
    </link>
    <!--  Joint 6-->
    <joint name="joint_6" type="revolute">
        <parent link="link_5" />
        <child link="link_6" />
        <origin rpy="0 0 0" xyz="0 0.0004 0.0723" />
        <axis xyz="1 0 0" />
        <!--changed from -1 to 1 March 22  -->
        <limit effort="20" lower="-2.0" upper="2.0" velocity="8" />
    </joint>
    <!-- Transmission 6 -->
    <transmission name="tran6">
        <type>transmission_interface/SimpleTransmission</type>
        <joint name="joint_6">
            <hardwareInterface>hardware_interface/PositionJointInterface</hardwareInterface>
        </joint>
        <actuator name="motor6">
            <hardwareInterface>hardware_interface/PositionJointInterface</hardwareInterface>
            <mechanicalReduction>1</mechanicalReduction>
        </actuator>
    </transmission>
    <!--  linear_link -->
    <link name="linear_link">
        <inertial>
            <mass value="0.0124248393645787" />
            <origin xyz="0.000135591479063887 2.77555756156289e-17 0.0459721322420806" rpy="0 0 0" />
            <inertia ixx="9.86019593697948e-07" ixy="3.29834778676727e-22" ixz="-5.36747709611266e-09" iyy="8.64419378255042e-07" iyz="-2.33368343375329e-23" izz="1.0672726099387e-06" />
        </inertial>
        <visual>
            <origin rpy="0 0 0" xyz="0 0 0" />
            <geometry>
                <mesh filename="package://touchscreen_robot_description_pkg/meshes/touchscreen_robot_la/linear_link.STL" />
            </geometry>
            <material name="">
                <color rgba="0.752941176470588 0.752941176470588 0.752941176470588 1" />
            </material>
        </visual>
        <collision>
            <origin rpy="0 0 0" xyz="0 0 0" />
            <geometry>
                <mesh filename="package://touchscreen_robot_description_pkg/meshes/touchscreen_robot_la/linear_link.STL" />
            </geometry>
        </collision>
    </link>
    <!-- Linear Joint -->
    <joint name="linear_joint" type="fixed">
        <origin rpy="0 0 0" xyz="-0.00025 0.003 0.105" />
        <parent link="link_6" />
        <child link="linear_link" />
        <axis xyz="0 0 1" />
        <limit effort="20" lower="0.0" upper="0.029" velocity="8" />
    </joint>
    <!-- Transmission 6 -->
    <transmission name="tranLinear">
        <type>transmission_interface/SimpleTransmission</type>
        <joint name="linear_joint">
            <hardwareInterface>hardware_interface/PositionJointInterface</hardwareInterface>
        </joint>
        <actuator name="motorLinear">
            <hardwareInterface>hardware_interface/PositionJointInterface</hardwareInterface>
            <mechanicalReduction>1</mechanicalReduction>
        </actuator>
    </transmission>
    <!-- Reference frame - link tip of stylus -->
    <link name="link_tip" />
    <!-- Reference frame - tip of stylus -->
    <!-- <joint name="joint_tip" type="fixed">
    <parent link="linear_link"/>
    <child link="link_tip"/>
    <origin xyz="0.00 0.00 0.0745" rpy="0 0 0" />
  </joint> -->
    <joint name="joint_tip" type="fixed">
        <parent link="link_6" />
        <child link="link_tip" />
        <origin rpy="0 0 0" xyz="0.00 0.00 0.1795" />
    </joint>
</robot>

